<?xml version="1.0"?>
<robot name="jetautoV2" xmlns:xacro="http://ros.org/wiki/xacro">

  
  <xacro:macro name="zm_roller_v0" params="prefix parent origin_x origin_y rotation_x rotation_z">
	<joint name="${prefix}_joint" type="continuous">
	  <parent link="${parent}"/>
	  <child link="${prefix}"/>
	  <origin xyz="${origin_x} ${origin_y} 0" rpy="${rotation_x} 0 ${rotation_z}"/>
      <axis xyz="0 0 1"/>
	  <dynamics damping="0.0" friction="0.0"/>
	</joint>

	<link name="${prefix}">
	  <visual>
	        <origin xyz="0 0 0" rpy="0 0 0"/>
		<geometry>
		  <mesh filename="package://jetauto_descriptionV2/meshes/mecanum_roller.stl" scale="0.00753846 0.00753846 0.00753846"/>
		</geometry>
		<material name="black"/>
	  </visual>
	  <collision>
		<geometry>
		  <mesh filename="package://jetauto_descriptionV2/meshes/mecanum_roller.stl" scale="0.00753846 0.00753846 0.00753846"/>
		</geometry>
	  </collision>
	  <inertial>
		<origin xyz="0 0 0" rpy="0 0 0"/>
        <mass value="0.0124"/>
        <inertia ixx="0.00051893" ixy="0.0" ixz="0.0" iyy="0.00051893" iyz="0.0" izz="0.00013891"/>
	  </inertial>
	</link>
  </xacro:macro>
  
</robot>
