<?xml version="1.0"?>
<robot name="jetautoV2" xmlns:xacro="http://ros.org/wiki/xacro">

  <xacro:property name="wheel_link_mass"    value="0.1" />
  <xacro:property name="wheel_link_radius"  value="0.0485"/>
  <xacro:property name="wheel_link_length"  value="0.04167"/>

  <xacro:macro name="zm_wheel_v2" params="prefix parent origin_x origin_y rotation_x">
	<joint name="wheel_joint_${prefix}" type="continuous">
	  <parent link="${parent}"/>
	  <child link="wheel_${prefix}"/>
	  <origin xyz="${origin_x} ${origin_y} 0" rpy="${rotation_x} 0 0"/>
      <axis xyz="0 0 1"/>
	  <dynamics damping="0.0" friction="0.0"/>
	</joint>

	<link name="wheel_${prefix}">
	  <visual>
	        <origin xyz="0 0 0" rpy="0 0 0"/>
		<geometry>
		  <mesh filename="package://jetauto_descriptionV2/meshes/mecanum_left_before.stl" scale="0.00753846 0.00753846 0.00753846"/>
		</geometry>
		<material name="white"/>
	  </visual>
	  <collision>
	  <origin xyz="0 0 0" rpy="0 0 0"/>
		<geometry>
		  <mesh filename="package://jetauto_descriptionV2/meshes/mecanum_left_before.stl" scale="0.00753846 0.00753846 0.00753846"/>
		</geometry>
	  </collision>

	  <!--<inertial>
          <origin xyz="0.001 0 0" rpy="0 0 0"/>
          <mass value="0.17"/>
          <inertia ixx="0.0004248052" ixy="0.0" ixz="0.0"
	               iyy="0.0004248045" iyz="0.0" izz="0.0004879970"/>
      </inertial>-->
        <xacro:cylinder_inertial m="${wheel_link_mass}" r="${wheel_link_radius}" h="${wheel_link_length}" />
	</link>
  </xacro:macro>
</robot>
